Fail
18.10.66.4: The expected value is: 1
18.10.66.4: The actual value is: Value Not found
Fail
18.10.72.1: The expected value is: 0
18.10.72.1: The actual value is: Value Not found
Fail
18.10.76.2.1: The expected value is: 1
18.10.76.2.1: The actual value is: Value Not found
Fail
18.10.76.2.1: The expected value is: Block
Traceback (most recent call last):
  File "c:\Users\DONHUANG\OneDrive - DNV\Project\Code\CIS Assessor Remote\Main.py", line 36, in get_registry_value
    stdout, stderr, rc = win_client.run_executable(
  File "C:\Users\DONHUANG\AppData\Local\anaconda3\lib\site-packages\pypsexec\client.py", line 398, in run_executable
    stdout_pipe = stdout(smb_tree, self._stdout_pipe_name)
  File "C:\Users\DONHUANG\AppData\Local\anaconda3\lib\site-packages\pypsexec\pipe.py", line 271, in __init__
    super(OutputPipeBytes, self).__init__(tree, name)
  File "C:\Users\DONHUANG\AppData\Local\anaconda3\lib\site-packages\pypsexec\pipe.py", line 186, in __init__
    self.pipe = open_pipe(tree, name,
    tree.session.connection.receive(request)
  File "C:\Users\DONHUANG\AppData\Local\anaconda3\lib\site-packages\smbprotocol\connection.py", line 1094, in receive
    raise SMBResponseException(response)
smbprotocol.exceptions.ObjectNameNotFound: Received unexpected status from the server: The object name is not found. (3221225524) STATUS_OBJECT_NAME_NOT_FOUND: 0xc0000034

During handling of the above exception, another exception occurred:

Traceback (most recent call last):
  File "c:\Users\DONHUANG\OneDrive - DNV\Project\Code\CIS Assessor Remote\Main.py", line 764, in <module>
    output_df = check_result(src_df)
  File "c:\Users\DONHUANG\OneDrive - DNV\Project\Code\CIS Assessor Remote\Main.py", line 271, in check_result
    actual_value = get_registry_value(reg_key, reg_item)
  File "c:\Users\DONHUANG\OneDrive - DNV\Project\Code\CIS Assessor Remote\Main.py", line 53, in get_registry_value
    return actual_value
UnboundLocalError: local variable 'actual_value' referenced before assignment